2024-12-16 13:51:27,825 - root - ERROR - 在插入新用户信息时出现错误，用户信息: <APP.model.entity.User.User object at 0x000002D30A87F010>，错误信息: (pymysql.err.OperationalError) (1045, "Access denied for user 'root'@'localhost' (using password: YES)")
(Background on this error at: https://sqlalche.me/e/20/e3q8)
Traceback (most recent call last):
  File "G:\web-AI\.venv\lib\site-packages\sqlalchemy\engine\base.py", line 146, in __init__
    self._dbapi_connection = engine.raw_connection()
  File "G:\web-AI\.venv\lib\site-packages\sqlalchemy\engine\base.py", line 3302, in raw_connection
    return self.pool.connect()
  File "G:\web-AI\.venv\lib\site-packages\sqlalchemy\pool\base.py", line 449, in connect
    return _ConnectionFairy._checkout(self)
  File "G:\web-AI\.venv\lib\site-packages\sqlalchemy\pool\base.py", line 1263, in _checkout
    fairy = _ConnectionRecord.checkout(pool)
  File "G:\web-AI\.venv\lib\site-packages\sqlalchemy\pool\base.py", line 712, in checkout
    rec = pool._do_get()
  File "G:\web-AI\.venv\lib\site-packages\sqlalchemy\pool\impl.py", line 179, in _do_get
    with util.safe_reraise():
  File "G:\web-AI\.venv\lib\site-packages\sqlalchemy\util\langhelpers.py", line 146, in __exit__
    raise exc_value.with_traceback(exc_tb)
  File "G:\web-AI\.venv\lib\site-packages\sqlalchemy\pool\impl.py", line 177, in _do_get
    return self._create_connection()
  File "G:\web-AI\.venv\lib\site-packages\sqlalchemy\pool\base.py", line 390, in _create_connection
    return _ConnectionRecord(self)
  File "G:\web-AI\.venv\lib\site-packages\sqlalchemy\pool\base.py", line 674, in __init__
    self.__connect()
  File "G:\web-AI\.venv\lib\site-packages\sqlalchemy\pool\base.py", line 900, in __connect
    with util.safe_reraise():
  File "G:\web-AI\.venv\lib\site-packages\sqlalchemy\util\langhelpers.py", line 146, in __exit__
    raise exc_value.with_traceback(exc_tb)
  File "G:\web-AI\.venv\lib\site-packages\sqlalchemy\pool\base.py", line 896, in __connect
    self.dbapi_connection = connection = pool._invoke_creator(self)
  File "G:\web-AI\.venv\lib\site-packages\sqlalchemy\engine\create.py", line 643, in connect
    return dialect.connect(*cargs, **cparams)
  File "G:\web-AI\.venv\lib\site-packages\sqlalchemy\engine\default.py", line 621, in connect
    return self.loaded_dbapi.connect(*cargs, **cparams)
  File "G:\web-AI\.venv\lib\site-packages\pymysql\connections.py", line 361, in __init__
    self.connect()
  File "G:\web-AI\.venv\lib\site-packages\pymysql\connections.py", line 669, in connect
    self._request_authentication()
  File "G:\web-AI\.venv\lib\site-packages\pymysql\connections.py", line 979, in _request_authentication
    auth_packet = _auth.caching_sha2_password_auth(self, auth_packet)
  File "G:\web-AI\.venv\lib\site-packages\pymysql\_auth.py", line 268, in caching_sha2_password_auth
    pkt = _roundtrip(conn, data)
  File "G:\web-AI\.venv\lib\site-packages\pymysql\_auth.py", line 121, in _roundtrip
    pkt = conn._read_packet()
  File "G:\web-AI\.venv\lib\site-packages\pymysql\connections.py", line 775, in _read_packet
    packet.raise_for_error()
  File "G:\web-AI\.venv\lib\site-packages\pymysql\protocol.py", line 219, in raise_for_error
    err.raise_mysql_exception(self._data)
  File "G:\web-AI\.venv\lib\site-packages\pymysql\err.py", line 150, in raise_mysql_exception
    raise errorclass(errno, errval)
pymysql.err.OperationalError: (1045, "Access denied for user 'root'@'localhost' (using password: YES)")

The above exception was the direct cause of the following exception:

Traceback (most recent call last):
  File "G:\web-AI\APP\model\operation\UserModel.py", line 50, in insert_user
    session.commit()
  File "G:\web-AI\.venv\lib\site-packages\sqlalchemy\orm\session.py", line 2028, in commit
    trans.commit(_to_root=True)
  File "<string>", line 2, in commit
  File "G:\web-AI\.venv\lib\site-packages\sqlalchemy\orm\state_changes.py", line 139, in _go
    ret_value = fn(self, *arg, **kw)
  File "G:\web-AI\.venv\lib\site-packages\sqlalchemy\orm\session.py", line 1313, in commit
    self._prepare_impl()
  File "<string>", line 2, in _prepare_impl
  File "G:\web-AI\.venv\lib\site-packages\sqlalchemy\orm\state_changes.py", line 139, in _go
    ret_value = fn(self, *arg, **kw)
  File "G:\web-AI\.venv\lib\site-packages\sqlalchemy\orm\session.py", line 1288, in _prepare_impl
    self.session.flush()
  File "G:\web-AI\.venv\lib\site-packages\sqlalchemy\orm\session.py", line 4352, in flush
    self._flush(objects)
  File "G:\web-AI\.venv\lib\site-packages\sqlalchemy\orm\session.py", line 4487, in _flush
    with util.safe_reraise():
  File "G:\web-AI\.venv\lib\site-packages\sqlalchemy\util\langhelpers.py", line 146, in __exit__
    raise exc_value.with_traceback(exc_tb)
  File "G:\web-AI\.venv\lib\site-packages\sqlalchemy\orm\session.py", line 4448, in _flush
    flush_context.execute()
  File "G:\web-AI\.venv\lib\site-packages\sqlalchemy\orm\unitofwork.py", line 466, in execute
    rec.execute(self)
  File "G:\web-AI\.venv\lib\site-packages\sqlalchemy\orm\unitofwork.py", line 642, in execute
    util.preloaded.orm_persistence.save_obj(
  File "G:\web-AI\.venv\lib\site-packages\sqlalchemy\orm\persistence.py", line 60, in save_obj
    for (
  File "G:\web-AI\.venv\lib\site-packages\sqlalchemy\orm\persistence.py", line 223, in _organize_states_for_save
    for state, dict_, mapper, connection in _connections_for_states(
  File "G:\web-AI\.venv\lib\site-packages\sqlalchemy\orm\persistence.py", line 1753, in _connections_for_states
    connection = uowtransaction.transaction.connection(base_mapper)
  File "<string>", line 2, in connection
  File "G:\web-AI\.venv\lib\site-packages\sqlalchemy\orm\state_changes.py", line 139, in _go
    ret_value = fn(self, *arg, **kw)
  File "G:\web-AI\.venv\lib\site-packages\sqlalchemy\orm\session.py", line 1039, in connection
    return self._connection_for_bind(bind, execution_options)
  File "<string>", line 2, in _connection_for_bind
  File "G:\web-AI\.venv\lib\site-packages\sqlalchemy\orm\state_changes.py", line 139, in _go
    ret_value = fn(self, *arg, **kw)
  File "G:\web-AI\.venv\lib\site-packages\sqlalchemy\orm\session.py", line 1175, in _connection_for_bind
    conn = self._parent._connection_for_bind(
  File "<string>", line 2, in _connection_for_bind
  File "G:\web-AI\.venv\lib\site-packages\sqlalchemy\orm\state_changes.py", line 139, in _go
    ret_value = fn(self, *arg, **kw)
  File "G:\web-AI\.venv\lib\site-packages\sqlalchemy\orm\session.py", line 1189, in _connection_for_bind
    conn = bind.connect()
  File "G:\web-AI\.venv\lib\site-packages\sqlalchemy\engine\base.py", line 3278, in connect
    return self._connection_cls(self)
  File "G:\web-AI\.venv\lib\site-packages\sqlalchemy\engine\base.py", line 148, in __init__
    Connection._handle_dbapi_exception_noconnection(
  File "G:\web-AI\.venv\lib\site-packages\sqlalchemy\engine\base.py", line 2442, in _handle_dbapi_exception_noconnection
    raise sqlalchemy_exception.with_traceback(exc_info[2]) from e
  File "G:\web-AI\.venv\lib\site-packages\sqlalchemy\engine\base.py", line 146, in __init__
    self._dbapi_connection = engine.raw_connection()
  File "G:\web-AI\.venv\lib\site-packages\sqlalchemy\engine\base.py", line 3302, in raw_connection
    return self.pool.connect()
  File "G:\web-AI\.venv\lib\site-packages\sqlalchemy\pool\base.py", line 449, in connect
    return _ConnectionFairy._checkout(self)
  File "G:\web-AI\.venv\lib\site-packages\sqlalchemy\pool\base.py", line 1263, in _checkout
    fairy = _ConnectionRecord.checkout(pool)
  File "G:\web-AI\.venv\lib\site-packages\sqlalchemy\pool\base.py", line 712, in checkout
    rec = pool._do_get()
  File "G:\web-AI\.venv\lib\site-packages\sqlalchemy\pool\impl.py", line 179, in _do_get
    with util.safe_reraise():
  File "G:\web-AI\.venv\lib\site-packages\sqlalchemy\util\langhelpers.py", line 146, in __exit__
    raise exc_value.with_traceback(exc_tb)
  File "G:\web-AI\.venv\lib\site-packages\sqlalchemy\pool\impl.py", line 177, in _do_get
    return self._create_connection()
  File "G:\web-AI\.venv\lib\site-packages\sqlalchemy\pool\base.py", line 390, in _create_connection
    return _ConnectionRecord(self)
  File "G:\web-AI\.venv\lib\site-packages\sqlalchemy\pool\base.py", line 674, in __init__
    self.__connect()
  File "G:\web-AI\.venv\lib\site-packages\sqlalchemy\pool\base.py", line 900, in __connect
    with util.safe_reraise():
  File "G:\web-AI\.venv\lib\site-packages\sqlalchemy\util\langhelpers.py", line 146, in __exit__
    raise exc_value.with_traceback(exc_tb)
  File "G:\web-AI\.venv\lib\site-packages\sqlalchemy\pool\base.py", line 896, in __connect
    self.dbapi_connection = connection = pool._invoke_creator(self)
  File "G:\web-AI\.venv\lib\site-packages\sqlalchemy\engine\create.py", line 643, in connect
    return dialect.connect(*cargs, **cparams)
  File "G:\web-AI\.venv\lib\site-packages\sqlalchemy\engine\default.py", line 621, in connect
    return self.loaded_dbapi.connect(*cargs, **cparams)
  File "G:\web-AI\.venv\lib\site-packages\pymysql\connections.py", line 361, in __init__
    self.connect()
  File "G:\web-AI\.venv\lib\site-packages\pymysql\connections.py", line 669, in connect
    self._request_authentication()
  File "G:\web-AI\.venv\lib\site-packages\pymysql\connections.py", line 979, in _request_authentication
    auth_packet = _auth.caching_sha2_password_auth(self, auth_packet)
  File "G:\web-AI\.venv\lib\site-packages\pymysql\_auth.py", line 268, in caching_sha2_password_auth
    pkt = _roundtrip(conn, data)
  File "G:\web-AI\.venv\lib\site-packages\pymysql\_auth.py", line 121, in _roundtrip
    pkt = conn._read_packet()
  File "G:\web-AI\.venv\lib\site-packages\pymysql\connections.py", line 775, in _read_packet
    packet.raise_for_error()
  File "G:\web-AI\.venv\lib\site-packages\pymysql\protocol.py", line 219, in raise_for_error
    err.raise_mysql_exception(self._data)
  File "G:\web-AI\.venv\lib\site-packages\pymysql\err.py", line 150, in raise_mysql_exception
    raise errorclass(errno, errval)
sqlalchemy.exc.OperationalError: (pymysql.err.OperationalError) (1045, "Access denied for user 'root'@'localhost' (using password: YES)")
(Background on this error at: https://sqlalche.me/e/20/e3q8)
2024-12-16 13:52:36,762 - root - ERROR - 在插入新用户信息时出现错误，用户信息: <APP.model.entity.User.User object at 0x0000014658B9FE50>，错误信息: (pymysql.err.IntegrityError) (1062, "Duplicate entry '<EMAIL>' for key 'users.email'")
[SQL: INSERT INTO `Users` (email, api_key, password, username) VALUES (%(email)s, %(api_key)s, %(password)s, %(username)s)]
[parameters: {'email': '<EMAIL>', 'api_key': '1231', 'password': '<PASSWORD>', 'username': '<EMAIL>'}]
(Background on this error at: https://sqlalche.me/e/20/gkpj)
Traceback (most recent call last):
  File "G:\web-AI\.venv\lib\site-packages\sqlalchemy\engine\base.py", line 1967, in _exec_single_context
    self.dialect.do_execute(
  File "G:\web-AI\.venv\lib\site-packages\sqlalchemy\engine\default.py", line 941, in do_execute
    cursor.execute(statement, parameters)
  File "G:\web-AI\.venv\lib\site-packages\pymysql\cursors.py", line 153, in execute
    result = self._query(query)
  File "G:\web-AI\.venv\lib\site-packages\pymysql\cursors.py", line 322, in _query
    conn.query(q)
  File "G:\web-AI\.venv\lib\site-packages\pymysql\connections.py", line 563, in query
    self._affected_rows = self._read_query_result(unbuffered=unbuffered)
  File "G:\web-AI\.venv\lib\site-packages\pymysql\connections.py", line 825, in _read_query_result
    result.read()
  File "G:\web-AI\.venv\lib\site-packages\pymysql\connections.py", line 1199, in read
    first_packet = self.connection._read_packet()
  File "G:\web-AI\.venv\lib\site-packages\pymysql\connections.py", line 775, in _read_packet
    packet.raise_for_error()
  File "G:\web-AI\.venv\lib\site-packages\pymysql\protocol.py", line 219, in raise_for_error
    err.raise_mysql_exception(self._data)
  File "G:\web-AI\.venv\lib\site-packages\pymysql\err.py", line 150, in raise_mysql_exception
    raise errorclass(errno, errval)
pymysql.err.IntegrityError: (1062, "Duplicate entry '<EMAIL>' for key 'users.email'")

The above exception was the direct cause of the following exception:

Traceback (most recent call last):
  File "G:\web-AI\APP\model\operation\UserModel.py", line 44, in insert_user
    session.commit()
  File "G:\web-AI\.venv\lib\site-packages\sqlalchemy\orm\session.py", line 2028, in commit
    trans.commit(_to_root=True)
  File "<string>", line 2, in commit
  File "G:\web-AI\.venv\lib\site-packages\sqlalchemy\orm\state_changes.py", line 139, in _go
    ret_value = fn(self, *arg, **kw)
  File "G:\web-AI\.venv\lib\site-packages\sqlalchemy\orm\session.py", line 1313, in commit
    self._prepare_impl()
  File "<string>", line 2, in _prepare_impl
  File "G:\web-AI\.venv\lib\site-packages\sqlalchemy\orm\state_changes.py", line 139, in _go
    ret_value = fn(self, *arg, **kw)
  File "G:\web-AI\.venv\lib\site-packages\sqlalchemy\orm\session.py", line 1288, in _prepare_impl
    self.session.flush()
  File "G:\web-AI\.venv\lib\site-packages\sqlalchemy\orm\session.py", line 4352, in flush
    self._flush(objects)
  File "G:\web-AI\.venv\lib\site-packages\sqlalchemy\orm\session.py", line 4487, in _flush
    with util.safe_reraise():
  File "G:\web-AI\.venv\lib\site-packages\sqlalchemy\util\langhelpers.py", line 146, in __exit__
    raise exc_value.with_traceback(exc_tb)
  File "G:\web-AI\.venv\lib\site-packages\sqlalchemy\orm\session.py", line 4448, in _flush
    flush_context.execute()
  File "G:\web-AI\.venv\lib\site-packages\sqlalchemy\orm\unitofwork.py", line 466, in execute
    rec.execute(self)
  File "G:\web-AI\.venv\lib\site-packages\sqlalchemy\orm\unitofwork.py", line 642, in execute
    util.preloaded.orm_persistence.save_obj(
  File "G:\web-AI\.venv\lib\site-packages\sqlalchemy\orm\persistence.py", line 93, in save_obj
    _emit_insert_statements(
  File "G:\web-AI\.venv\lib\site-packages\sqlalchemy\orm\persistence.py", line 1233, in _emit_insert_statements
    result = connection.execute(
  File "G:\web-AI\.venv\lib\site-packages\sqlalchemy\engine\base.py", line 1418, in execute
    return meth(
  File "G:\web-AI\.venv\lib\site-packages\sqlalchemy\sql\elements.py", line 515, in _execute_on_connection
    return connection._execute_clauseelement(
  File "G:\web-AI\.venv\lib\site-packages\sqlalchemy\engine\base.py", line 1640, in _execute_clauseelement
    ret = self._execute_context(
  File "G:\web-AI\.venv\lib\site-packages\sqlalchemy\engine\base.py", line 1846, in _execute_context
    return self._exec_single_context(
  File "G:\web-AI\.venv\lib\site-packages\sqlalchemy\engine\base.py", line 1986, in _exec_single_context
    self._handle_dbapi_exception(
  File "G:\web-AI\.venv\lib\site-packages\sqlalchemy\engine\base.py", line 2355, in _handle_dbapi_exception
    raise sqlalchemy_exception.with_traceback(exc_info[2]) from e
  File "G:\web-AI\.venv\lib\site-packages\sqlalchemy\engine\base.py", line 1967, in _exec_single_context
    self.dialect.do_execute(
  File "G:\web-AI\.venv\lib\site-packages\sqlalchemy\engine\default.py", line 941, in do_execute
    cursor.execute(statement, parameters)
  File "G:\web-AI\.venv\lib\site-packages\pymysql\cursors.py", line 153, in execute
    result = self._query(query)
  File "G:\web-AI\.venv\lib\site-packages\pymysql\cursors.py", line 322, in _query
    conn.query(q)
  File "G:\web-AI\.venv\lib\site-packages\pymysql\connections.py", line 563, in query
    self._affected_rows = self._read_query_result(unbuffered=unbuffered)
  File "G:\web-AI\.venv\lib\site-packages\pymysql\connections.py", line 825, in _read_query_result
    result.read()
  File "G:\web-AI\.venv\lib\site-packages\pymysql\connections.py", line 1199, in read
    first_packet = self.connection._read_packet()
  File "G:\web-AI\.venv\lib\site-packages\pymysql\connections.py", line 775, in _read_packet
    packet.raise_for_error()
  File "G:\web-AI\.venv\lib\site-packages\pymysql\protocol.py", line 219, in raise_for_error
    err.raise_mysql_exception(self._data)
  File "G:\web-AI\.venv\lib\site-packages\pymysql\err.py", line 150, in raise_mysql_exception
    raise errorclass(errno, errval)
sqlalchemy.exc.IntegrityError: (pymysql.err.IntegrityError) (1062, "Duplicate entry '<EMAIL>' for key 'users.email'")
[SQL: INSERT INTO `Users` (email, api_key, password, username) VALUES (%(email)s, %(api_key)s, %(password)s, %(username)s)]
[parameters: {'email': '<EMAIL>', 'api_key': '1231', 'password': '<PASSWORD>', 'username': '<EMAIL>'}]
(Background on this error at: https://sqlalche.me/e/20/gkpj)
2024-12-16 13:55:56,557 - root - ERROR - 在插入新用户信息时出现错误，用户信息: <APP.model.entity.User.User object at 0x0000019BD905FE50>，错误信息: (pymysql.err.IntegrityError) (1048, "Column 'api_key' cannot be null")
[SQL: INSERT INTO `Users` (email, api_key, password, username) VALUES (%(email)s, %(api_key)s, %(password)s, %(username)s)]
[parameters: {'email': '<EMAIL>', 'api_key': None, 'password': '<PASSWORD>', 'username': 'test'}]
(Background on this error at: https://sqlalche.me/e/20/gkpj)
Traceback (most recent call last):
  File "G:\web-AI\.venv\lib\site-packages\sqlalchemy\engine\base.py", line 1967, in _exec_single_context
    self.dialect.do_execute(
  File "G:\web-AI\.venv\lib\site-packages\sqlalchemy\engine\default.py", line 941, in do_execute
    cursor.execute(statement, parameters)
  File "G:\web-AI\.venv\lib\site-packages\pymysql\cursors.py", line 153, in execute
    result = self._query(query)
  File "G:\web-AI\.venv\lib\site-packages\pymysql\cursors.py", line 322, in _query
    conn.query(q)
  File "G:\web-AI\.venv\lib\site-packages\pymysql\connections.py", line 563, in query
    self._affected_rows = self._read_query_result(unbuffered=unbuffered)
  File "G:\web-AI\.venv\lib\site-packages\pymysql\connections.py", line 825, in _read_query_result
    result.read()
  File "G:\web-AI\.venv\lib\site-packages\pymysql\connections.py", line 1199, in read
    first_packet = self.connection._read_packet()
  File "G:\web-AI\.venv\lib\site-packages\pymysql\connections.py", line 775, in _read_packet
    packet.raise_for_error()
  File "G:\web-AI\.venv\lib\site-packages\pymysql\protocol.py", line 219, in raise_for_error
    err.raise_mysql_exception(self._data)
  File "G:\web-AI\.venv\lib\site-packages\pymysql\err.py", line 150, in raise_mysql_exception
    raise errorclass(errno, errval)
pymysql.err.IntegrityError: (1048, "Column 'api_key' cannot be null")

The above exception was the direct cause of the following exception:

Traceback (most recent call last):
  File "G:\web-AI\APP\model\operation\UserModel.py", line 44, in insert_user
    session.commit()
  File "G:\web-AI\.venv\lib\site-packages\sqlalchemy\orm\session.py", line 2028, in commit
    trans.commit(_to_root=True)
  File "<string>", line 2, in commit
  File "G:\web-AI\.venv\lib\site-packages\sqlalchemy\orm\state_changes.py", line 139, in _go
    ret_value = fn(self, *arg, **kw)
  File "G:\web-AI\.venv\lib\site-packages\sqlalchemy\orm\session.py", line 1313, in commit
    self._prepare_impl()
  File "<string>", line 2, in _prepare_impl
  File "G:\web-AI\.venv\lib\site-packages\sqlalchemy\orm\state_changes.py", line 139, in _go
    ret_value = fn(self, *arg, **kw)
  File "G:\web-AI\.venv\lib\site-packages\sqlalchemy\orm\session.py", line 1288, in _prepare_impl
    self.session.flush()
  File "G:\web-AI\.venv\lib\site-packages\sqlalchemy\orm\session.py", line 4352, in flush
    self._flush(objects)
  File "G:\web-AI\.venv\lib\site-packages\sqlalchemy\orm\session.py", line 4487, in _flush
    with util.safe_reraise():
  File "G:\web-AI\.venv\lib\site-packages\sqlalchemy\util\langhelpers.py", line 146, in __exit__
    raise exc_value.with_traceback(exc_tb)
  File "G:\web-AI\.venv\lib\site-packages\sqlalchemy\orm\session.py", line 4448, in _flush
    flush_context.execute()
  File "G:\web-AI\.venv\lib\site-packages\sqlalchemy\orm\unitofwork.py", line 466, in execute
    rec.execute(self)
  File "G:\web-AI\.venv\lib\site-packages\sqlalchemy\orm\unitofwork.py", line 642, in execute
    util.preloaded.orm_persistence.save_obj(
  File "G:\web-AI\.venv\lib\site-packages\sqlalchemy\orm\persistence.py", line 93, in save_obj
    _emit_insert_statements(
  File "G:\web-AI\.venv\lib\site-packages\sqlalchemy\orm\persistence.py", line 1233, in _emit_insert_statements
    result = connection.execute(
  File "G:\web-AI\.venv\lib\site-packages\sqlalchemy\engine\base.py", line 1418, in execute
    return meth(
  File "G:\web-AI\.venv\lib\site-packages\sqlalchemy\sql\elements.py", line 515, in _execute_on_connection
    return connection._execute_clauseelement(
  File "G:\web-AI\.venv\lib\site-packages\sqlalchemy\engine\base.py", line 1640, in _execute_clauseelement
    ret = self._execute_context(
  File "G:\web-AI\.venv\lib\site-packages\sqlalchemy\engine\base.py", line 1846, in _execute_context
    return self._exec_single_context(
  File "G:\web-AI\.venv\lib\site-packages\sqlalchemy\engine\base.py", line 1986, in _exec_single_context
    self._handle_dbapi_exception(
  File "G:\web-AI\.venv\lib\site-packages\sqlalchemy\engine\base.py", line 2355, in _handle_dbapi_exception
    raise sqlalchemy_exception.with_traceback(exc_info[2]) from e
  File "G:\web-AI\.venv\lib\site-packages\sqlalchemy\engine\base.py", line 1967, in _exec_single_context
    self.dialect.do_execute(
  File "G:\web-AI\.venv\lib\site-packages\sqlalchemy\engine\default.py", line 941, in do_execute
    cursor.execute(statement, parameters)
  File "G:\web-AI\.venv\lib\site-packages\pymysql\cursors.py", line 153, in execute
    result = self._query(query)
  File "G:\web-AI\.venv\lib\site-packages\pymysql\cursors.py", line 322, in _query
    conn.query(q)
  File "G:\web-AI\.venv\lib\site-packages\pymysql\connections.py", line 563, in query
    self._affected_rows = self._read_query_result(unbuffered=unbuffered)
  File "G:\web-AI\.venv\lib\site-packages\pymysql\connections.py", line 825, in _read_query_result
    result.read()
  File "G:\web-AI\.venv\lib\site-packages\pymysql\connections.py", line 1199, in read
    first_packet = self.connection._read_packet()
  File "G:\web-AI\.venv\lib\site-packages\pymysql\connections.py", line 775, in _read_packet
    packet.raise_for_error()
  File "G:\web-AI\.venv\lib\site-packages\pymysql\protocol.py", line 219, in raise_for_error
    err.raise_mysql_exception(self._data)
  File "G:\web-AI\.venv\lib\site-packages\pymysql\err.py", line 150, in raise_mysql_exception
    raise errorclass(errno, errval)
sqlalchemy.exc.IntegrityError: (pymysql.err.IntegrityError) (1048, "Column 'api_key' cannot be null")
[SQL: INSERT INTO `Users` (email, api_key, password, username) VALUES (%(email)s, %(api_key)s, %(password)s, %(username)s)]
[parameters: {'email': '<EMAIL>', 'api_key': None, 'password': '<PASSWORD>', 'username': 'test'}]
(Background on this error at: https://sqlalche.me/e/20/gkpj)
